
<mujoco model="leg">
  <option timestep="0.005"/>

  <visual>
    <map force="0.1" zfar="30"/>
    <rgba haze="0.15 0.25 0.35 1"/>
    <global offwidth="2560" offheight="1440" elevation="-20" azimuth="120"/>
  </visual>

  <asset>
    <texture type="skybox" builtin="gradient" rgb1=".3 .5 .7" rgb2="0 0 0" width="32" height="512"/>
    <texture name="body" type="cube" builtin="flat" mark="cross" width="128" height="128" rgb1="0.9 0.9 0.9" rgb2="0.9 0.9 0.9" markrgb="1 1 1"/>
    <material name="body" texture="body" texuniform="true" rgba="0.9 0.9 0.9 .5"/>
    <texture name="grid" type="2d" builtin="checker" width="512" height="512" rgb1=".1 .2 .3" rgb2=".2 .3 .4"/>
    <material name="grid" texture="grid" texrepeat="1 1" texuniform="true" reflectance=".2"/>
  </asset>

  <default>
    <motor ctrlrange="-1 1" ctrllimited="true"/>
    <default class="body">

      <!-- geoms -->
      <geom type="box" condim="1" friction=".7" solimp=".9 .99 .003" solref=".015 1" material="body" group="1"/>
      <default class="support">
        <geom fromto="-1 0 0 2 0 0"  size=".02"/>
      </default>
      <default class="pulley_wheel_left">
        <geom type="cylinder" fromto="0 -0.05500000000000001 0 0 0 0" size="0.02"/>
      </default>
      <default class="pulley_wheel_right">
        <geom type="cylinder" fromto="0 0 0 0 0.05500000000000001 0" size="0.02"/>
      </default>
      <default class="spine">
        <geom fromto="0 0 0.06 -0.4925 0 0"  size=".015"/>
      </default>
      <default class="scapula">
        <geom fromto="0 0 0 0 0 -0.17"  size=".01"/>
      </default>
      <default class="humerus">
        <geom fromto="0 0 0 0 0 -0.1925"  size=".01"/>
      </default>
      <default class="radius">
        <geom fromto="0 0 0 0 0 -0.2125"  size=".01"/>
      </default>
      <default class="hand">
        <geom fromto="0 0 0 0 0 -0.13" size=".01"/>
      </default>
      <default class="femur">
        <geom fromto="0 0 0 0 0 -0.2225" size=".01"/>
      </default>
      <default class="tibia">
        <geom fromto="0 0 0 0 0 -0.22" size=".01"/>
      </default>
      <default class="foot">
        <geom fromto="0 0 0 0 0 -0.16" size=".01"/>
      </default>

      <!-- joints -->
      <joint type="hinge" damping=".01" stiffness="0" armature=".01" limited="true" solimplimit="0 .99 .01"/>
      <default class="support_joint_horizontal">
        <joint type="slide" range="-1 30" pos="0 0 0" axis="1 0 0" stiffness="0.2"/>
      </default>
      <default class="support_joint_vertical">
        <joint type="slide" range="0.1 2" pos="0 0 0" axis="0 0 1" stiffness="0.2"/>
      </default>
      <default class="support_joint_sagittal_rotation">
        <joint type="hinge" range="-8 -5" pos="0 0 0" axis="0 1 0" stiffness="0.2"/>
      </default>
      <default class="scapula_joint">
        <joint range="-50 40" pos="0 0 0" axis="0 1 0" stiffness="0.2"/>
      </default>
      <default class="shoulder_joint">
        <joint range="0 90" pos="0 0 0" axis="0 1 0" stiffness="0.2"/>
      </default>
      <default class="elbow_joint">
        <joint range="-90 0" pos="0 0 0" axis="0 1 0" stiffness="0.2"/>
      </default>
      <default class="wrist_joint">
        <joint range="-90 0" pos="0 0 0" axis="0 1 0" stiffness="0.2"/>
      </default>
      <default class="hip_joint">
        <joint range="-60 40" pos="0 0 0" axis="0 1 0" stiffness="0.2"/>
      </default>
      <default class="knee_joint">
        <joint range="0 85" pos="0 0 0" axis="0 1 0" stiffness="0.2"/>
      </default>
      <default class="ankle_joint">
        <joint range="-90 0" pos="0 0 0" axis="0 1 0" stiffness="0.2"/>
      </default>

      <!-- ext site = blue, flx site = green -->
      <default class="site_ext">
        <site rgba=".1 .1 1 1"/>
      </default>
      <default class="site_flx">
        <site rgba=".1 1 .1 1"/>
      </default>
      <default class="site_pass">
        <site rgba="1 1 .1 1"/>
      </default>

    </default>

    <!-- muscles -->
    <default class="muscle">
      <!-- Max human calf strength: 148.5 +/- 40.2 Nm (Trappe et al.,. 2001. Calf strength in humans) (STU)-->
      <!-- Thus, force = 148.5 Nm / 0.075 m = 1980 N = 19.8 scaled (STU)-->
      <!-- To keep gain values low, triple magnitude: force = 3 * 19.8 = 59.4 ~ 60 (STU)-->
      <muscle ctrllimited="true" ctrlrange="0 1" force="60"/>
    </default>
  </default>

  <worldbody>
    <geom name="floor" size="0 0 5" type="plane" material="grid" condim="3" friction="5 0.005 0.0001"/>4
    <!-- <geom name="obstacle" size="1 .1 .08" type="box" pos="1 0.05 0"/> -->
    <body name="support" pos="0 0 2" childclass="body">
      <light name="top" pos="-.5 -.5 2" mode="trackcom"/>
      <geom name="support" class="support"/>
      <body name="spine" pos="-1 0 -1.3" childclass="body">
        <camera name="close" pos="0.194 -1.139 0.530" xyaxes="0.929 0.370 -0.000 -0.206 0.517 0.831"/>
        <joint name="support_horizontal" pos="-.245 0 0" class="support_joint_horizontal"/>
        <joint name="support_vertical" pos="-.245 0 0" class="support_joint_vertical"/>
        <!-- <joint name="support_sagittal_rotation" pos="0 0 0" class="support_joint_sagittal_rotation"/> -->
        <geom name="spine" class="spine"/>
        <site name="spine_hip_L_ext_site" pos="-0.083 0.06999999999999999  0.037" class="site_ext"/>
        <site name="spine_hip_L_flx_site" pos="-0.083 0.06999999999999999  0.015" class="site_flx"/>
        <site name="spine_hip_R_ext_site" pos="-0.083 -0.06999999999999999 0.037" class="site_ext"/>
        <site name="spine_hip_R_flx_site" pos="-0.083 -0.06999999999999999 0.015" class="site_flx"/>
        <site name="spine_scapula_L_ext_site" pos="-0.405 0.06999999999999999 0.045" class="site_ext"/>
        <site name="spine_scapula_L_flx_site" pos="-0.405 0.06999999999999999 0.023" class="site_flx"/>
        <site name="spine_scapula_R_ext_site" pos="-0.405 -0.06999999999999999 0.045" class="site_ext"/>
        <site name="spine_scapula_R_flx_site" pos="-0.405 -0.06999999999999999 0.023" class="site_flx"/>
        <site name="spine_hip_L_ext_site_pass" pos="-0.508 0.06999999999999999 -0.004900000000000002" class="site_pass"/>
        <site name="spine_hip_L_flx_site_pass" pos="-0.508 0.06999999999999999 -0.0451" class="site_pass"/>
        <site name="spine_hip_R_ext_site_pass" pos="-0.508 -0.06999999999999999 -0.004900000000000002" class="site_pass"/>
        <site name="spine_hip_R_flx_site_pass" pos="-0.508 -0.06999999999999999 -0.0451" class="site_pass"/>
        <site name="spine_scapula_L_ext_site_pass" pos="0 0.06999999999999999 0.1051" class="site_pass"/>
        <site name="spine_scapula_L_flx_site_pass" pos="0 0.06999999999999999 0.064900000000000002" class="site_pass"/>
        <site name="spine_scapula_R_ext_site_pass" pos="0 -0.06999999999999999 0.1051" class="site_pass"/>
        <site name="spine_scapula_R_flx_site_pass" pos="0 -0.06999999999999999 0.064900000000000002" class="site_pass"/>

        <body name="leg_rear_left" pos="-0.508 0.105 -0.025" childclass="body">
          <body name="femur_left" pos="0 0 0">
              <joint name="L_hip_joint" class="hip_joint"/>
              <geom name="femur_left" class="femur"/>
              <site name="femur_knee_L_ext_site" pos="0.024 0 0.025" class="site_ext"/>
              <site name="femur_knee_L_flx_site" pos="-0.024 0 0.025" class="site_flx"/>
              <site name="femur_knee_L_ext_site_pass" pos="0.0225 0 -0.2025" class="site_pass"/>
              <site name="femur_knee_L_flx_site_pass" pos="-0.0225 0 -0.2025" class="site_pass"/>
              <body name="pulley_wheel_left_rear" pos="0 0 0">
                  <geom name="pulley_hip_left" class="pulley_wheel_left"/>
                  <site name="pulley_hip_L_ext_site" pos="-0.0201 -0.035 0.0001" class="site_ext"/>
                  <site name="pulley_hip_L_flx_site" pos="-0.0201 -0.035 -0.0001" class="site_flx"/>
              </body>
              <body name="tibia_left" pos="0 0 -0.2225">
                  <joint name="L_knee_joint" class="knee_joint"/>
                  <geom name="tibia_left" class="tibia"/>
                  <site name="tibia_knee_L_ext_site" pos="0.016 0 0.007" class="site_ext"/>
                  <site name="tibia_knee_L_flx_site" pos="-0.015 0 -0.013" class="site_flx"/>
                  <site name="tibia_ankle_L_ext_site" pos="-0.025 0 -0.034" class="site_ext"/>
                  <site name="tibia_ankle_L_flx_site" pos="0.020 0 -0.006" class="site_flx"/>
                  <site name="tibia_ankle_L_ext_site_pass" pos="-0.0225 0 -0.20" class="site_pass"/>
                  <site name="tibia_ankle_L_flx_site_pass" pos="0.0225 0 -0.20" class="site_pass"/>
                  <body name="foot_left" pos="0 0 -0.22">
                      <joint name="L_ankle_joint" class="ankle_joint"/>
                      <geom name="foot_left" class="foot"/>
                      <site name="foot_ankle_L_ext_site" pos="-0.020 0 0.0100" class="site_ext"/>
                      <site name="foot_ankle_L_flx_site" pos="0.0075 0 -0.015" class="site_flx"/>
                  </body>
              </body>
          </body>
        </body>

        <body name="leg_rear_right" pos="-.508 -0.105 -0.025" childclass="body">
          <body name="femur_right" pos="0 0 0">
              <joint name="R_hip_joint" class="hip_joint"/>
              <geom name="femur_right" class="femur"/>
              <site name="femur_knee_R_ext_site" pos="0.024 0 0.025" class="site_ext"/>
              <site name="femur_knee_R_flx_site" pos="-0.024 0 0.025" class="site_flx"/>
              <site name="femur_knee_R_ext_site_pass" pos="0.0225 0 -0.2025" class="site_pass"/>
              <site name="femur_knee_R_flx_site_pass" pos="-0.0225 0 -0.2025" class="site_pass"/>
              <body name="pulley_wheel_right_rear" pos="0 0 0">
                  <geom name="pulley_hip_right" class="pulley_wheel_right"/>
                  <site name="pulley_hip_R_ext_site" pos="-0.0201 0.035 0.0001" class="site_ext"/>
                  <site name="pulley_hip_R_flx_site" pos="-0.0201 0.035 -0.0001" class="site_flx"/>
              </body>
              <body name="tibia_right" pos="0 0 -0.2225">
                  <joint name="R_knee_joint" class="knee_joint"/>
                  <geom name="tibia_right" class="tibia"/>
                  <site name="tibia_knee_R_ext_site" pos="0.016 0 0.007" class="site_ext"/>
                  <site name="tibia_knee_R_flx_site" pos="-0.015 0 -0.013" class="site_flx"/>
                  <site name="tibia_ankle_R_ext_site" pos="-0.025 0 -0.034" class="site_ext"/>
                  <site name="tibia_ankle_R_flx_site" pos="0.020 0 -0.006" class="site_flx"/>
                  <site name="tibia_ankle_R_ext_site_pass" pos="-0.0225 0 -0.20" class="site_pass"/>
                  <site name="tibia_ankle_R_flx_site_pass" pos="0.0225 0 -0.20" class="site_pass"/>
                  <body name="foot_right" pos="0 0 -0.22">
                      <joint name="R_ankle_joint" class="ankle_joint"/>
                      <geom name="foot_right" class="foot"/>
                      <site name="foot_ankle_R_ext_site" pos="-0.020 0 0.0100" class="site_ext"/>
                      <site name="foot_ankle_R_flx_site" pos="0.0075 0 -0.015" class="site_flx"/>
                  </body>
              </body>
          </body>
        </body>

        <body name="leg_front_left" pos="0 0.105 0.085" childclass="body">
            <body name="scapula_left" pos="0 0 0">
                <joint name="L_scapula_joint" class="scapula_joint"/>
                <geom name="scapula_left" class="scapula"/>
                <site name="scapula_shoulder_L_ext_site" pos="0.024 0 0.025" class="site_ext"/>
                <site name="scapula_shoulder_L_flx_site" pos="-0.024 0 0.025" class="site_flx"/>
                <site name="scapula_shoulder_L_ext_site_pass" pos="0.0225 0 -0.15" class="site_pass"/>
                <site name="scapula_shoulder_L_flx_site_pass" pos="-0.0225 0 -0.15" class="site_pass"/>
                <body name="pulley_wheel_left_front" pos="0 0 0">
                    <geom name="pulley_scapula_left" class="pulley_wheel_left"/>
                    <site name="pulley_scapula_L_ext_site" pos="0.0201 -0.035 0.0001" class="site_ext"/>
                    <site name="pulley_scapula_L_flx_site" pos="0.0201 -0.035 -0.0001" class="site_flx"/>
                </body>
                <body name="humerus_left" pos="0 0 -0.17">
                    <joint name="L_shoulder_joint" class="shoulder_joint"/>
                    <geom name="humerus_left" class="humerus"/>
                    <site name="humerus_shoulder_L_ext_site" pos="0.022 0 0.011" class="site_ext"/>
                    <site name="humerus_shoulder_L_flx_site" pos="-0.011 0 -0.015" class="site_flx"/>
                    <body name="radius_left" pos="0 0 -0.1925">
                        <joint name="L_elbow_joint" class="elbow_joint"/>
                        <geom name="radius_left" class="radius"/>]
                        <site name="radius_wrist_L_ext_site" pos="-0.023 0 0.016" class="site_ext"/>
                        <site name="radius_wrist_L_flx_site" pos="0.023 0 -0.023" class="site_flx"/>
                        <body name="hand_left" pos="0 0 -0.2125">
                            <joint name="L_wrist_joint" class="wrist_joint"/>
                            <geom name="hand_left" class="hand"/>
                            <site name="hand_wrist_L_ext_site" pos="-0.01 0 0.02" class="site_ext"/>
                            <site name="hand_wrist_L_flx_site" pos="0.0075 0 -0.015" class="site_flx"/>
                        </body>
                    </body>
                </body>
                <body name="humerus_left_0" pos="-0.03 0 -0.14">
                    <joint name="L_pantograph_joint" class="shoulder_joint"/>
                    <geom name="humerus_left_0" class="humerus"/>
                </body>
            </body>
        </body>

        <body name="leg_front_right" pos="0 -0.105 0.085" childclass="body">
            <body name="scapula_right" pos="0 0 0">
                <joint name="R_scapula_joint" class="scapula_joint"/>
                <geom name="scapula_right" class="scapula"/>
                <site name="scapula_shoulder_R_ext_site" pos="0.024 0 0.025" class="site_ext"/>
                <site name="scapula_shoulder_R_flx_site" pos="-0.024 0 0.025" class="site_flx"/>
                <site name="scapula_shoulder_R_ext_site_pass" pos="0.0225 0 -0.15" class="site_pass"/>
                <site name="scapula_shoulder_R_flx_site_pass" pos="-0.0225 0 -0.15" class="site_pass"/>
                <body name="pulley_wheel_right_front" pos="0 0 0">
                    <geom name="pulley_scapula_right" class="pulley_wheel_right"/>
                    <site name="pulley_scapula_R_ext_site" pos="0.0201 0.035 0.0001" class="site_ext"/>
                    <site name="pulley_scapula_R_flx_site" pos="0.0201 0.035 -0.0001" class="site_flx"/>
                </body>
                <body name="humerus_right" pos="0 0 -0.17">
                    <joint name="R_shoulder_joint" class="shoulder_joint"/>
                    <geom name="humerus_right" class="humerus"/>
                    <site name="humerus_shoulder_R_ext_site" pos="0.022 0 0.011" class="site_ext"/>
                    <site name="humerus_shoulder_R_flx_site" pos="-0.011 0 -0.015" class="site_flx"/>
                    <body name="radius_right" pos="0 0 -0.1925">
                        <joint name="R_elbow_joint" class="elbow_joint"/>
                        <geom name="radius_right" class="radius"/>]
                        <site name="radius_wrist_R_ext_site" pos="-0.023 0 0.016" class="site_ext"/>
                        <site name="radius_wrist_R_flx_site" pos="0.023 0 -0.023" class="site_flx"/>
                        <body name="hand_right" pos="0 0 -0.2125">
                            <joint name="R_wrist_joint" class="wrist_joint"/>
                            <geom name="hand_right" class="hand"/>
                            <site name="hand_wrist_R_ext_site" pos="-0.01 0 0.02" class="site_ext"/>
                            <site name="hand_wrist_R_flx_site" pos="0.0075 0 -0.015" class="site_flx"/>
                        </body>
                    </body>
                </body>
                <body name="humerus_right_0" pos="-0.03 0 -0.14">
                    <joint name="R_pantograph_joint" class="shoulder_joint"/>
                    <geom name="humerus_right_0" class="humerus"/>
                </body>
            </body>
        </body>

      </body>
    </body>
  </worldbody>

  <tendon>
    <spatial name="hip_L_ext_tendon" rgba=".95 .3 .3 1">
        <site site="spine_hip_L_ext_site"/>
        <site site="spine_hip_L_ext_site_pass"/>
        <geom geom="pulley_hip_left"/>
        <site site="pulley_hip_L_ext_site"/>
    </spatial>
    <spatial name="hip_L_flx_tendon" rgba=".95 .3 .3 1">
        <site site="spine_hip_L_flx_site"/>
        <site site="spine_hip_L_flx_site_pass"/>
        <geom geom="pulley_hip_left"/>
        <site site="pulley_hip_L_flx_site"/>
    </spatial>

    <spatial name="hip_R_ext_tendon" rgba=".95 .3 .3 1">
        <site site="spine_hip_R_ext_site"/>
        <site site="spine_hip_R_ext_site_pass"/>
        <geom geom="pulley_hip_right"/>
        <site site="pulley_hip_R_ext_site"/>
    </spatial>
    <spatial name="hip_R_flx_tendon" rgba=".95 .3 .3 1">
        <site site="spine_hip_R_flx_site"/>
        <site site="spine_hip_R_flx_site_pass"/>
        <geom geom="pulley_hip_right"/>
        <site site="pulley_hip_R_flx_site"/>
    </spatial>

    <spatial name="knee_L_ext_tendon" rgba=".95 .3 .3 1">
        <site site="femur_knee_L_ext_site"/>
        <site site="femur_knee_L_ext_site_pass"/> 
        <site site="tibia_knee_L_ext_site"/>
    </spatial>
    <spatial name="knee_L_flx_tendon" rgba=".95 .3 .3 1">
        <site site="femur_knee_L_flx_site"/>
        <site site="femur_knee_L_flx_site_pass"/> 
        <site site="tibia_knee_L_flx_site"/>
    </spatial>

    <spatial name="knee_R_ext_tendon" rgba=".95 .3 .3 1">
        <site site="femur_knee_R_ext_site"/>
        <site site="femur_knee_R_ext_site_pass"/> 
        <site site="tibia_knee_R_ext_site"/>
    </spatial>
    <spatial name="knee_R_flx_tendon" rgba=".95 .3 .3 1">
        <site site="femur_knee_R_flx_site"/>
        <site site="femur_knee_R_flx_site_pass"/> 
        <site site="tibia_knee_R_flx_site"/>
    </spatial>

    <spatial name="ankle_L_ext_tendon" rgba=".95 .3 .3 1">
        <site site="tibia_ankle_L_ext_site"/>
        <site site="tibia_ankle_L_ext_site_pass"/>
        <site site="foot_ankle_L_ext_site"/>
    </spatial>
    <spatial name="ankle_L_flx_tendon" rgba=".95 .3 .3 1">
        <site site="tibia_ankle_L_flx_site"/>
        <site site="tibia_ankle_L_flx_site_pass"/>
        <site site="foot_ankle_L_flx_site"/>
    </spatial>

    <spatial name="ankle_R_ext_tendon" rgba=".95 .3 .3 1">
        <site site="tibia_ankle_R_ext_site"/>
        <site site="tibia_ankle_R_ext_site_pass"/>
        <site site="foot_ankle_R_ext_site"/>
    </spatial>
    <spatial name="ankle_R_flx_tendon" rgba=".95 .3 .3 1">
        <site site="tibia_ankle_R_flx_site"/>
        <site site="tibia_ankle_R_flx_site_pass"/>
        <site site="foot_ankle_R_flx_site"/>
    </spatial>

    <spatial name="scapula_L_ext_tendon" rgba=".95 .3 .3 1">
        <site site="spine_scapula_L_ext_site"/>
        <site site="spine_scapula_L_ext_site_pass"/>
        <geom geom="pulley_scapula_left"/>
        <site site="pulley_scapula_L_ext_site"/>
    </spatial>
    <spatial name="scapula_L_flx_tendon" rgba=".95 .3 .3 1">
        <site site="spine_scapula_L_flx_site"/>
        <site site="spine_scapula_L_flx_site_pass"/>
        <geom geom="pulley_scapula_left"/>
        <site site="pulley_scapula_L_flx_site"/>
    </spatial>

    <spatial name="scapula_R_ext_tendon" rgba=".95 .3 .3 1">
        <site site="spine_scapula_R_ext_site"/>
        <site site="spine_scapula_R_ext_site_pass"/>
        <geom geom="pulley_scapula_right"/>
        <site site="pulley_scapula_R_ext_site"/>
    </spatial>
    <spatial name="scapula_R_flx_tendon" rgba=".95 .3 .3 1">
        <site site="spine_scapula_R_flx_site"/>
        <site site="spine_scapula_R_flx_site_pass"/>
        <geom geom="pulley_scapula_right"/>
        <site site="pulley_scapula_R_flx_site"/>
    </spatial>

    <spatial name="shoulder_L_ext_tendon" rgba=".95 .3 .3 1">
        <site site="scapula_shoulder_L_ext_site"/>
        <site site="scapula_shoulder_L_ext_site_pass"/>
        <site site="humerus_shoulder_L_ext_site"/>
    </spatial>
    <spatial name="shoulder_L_flx_tendon" rgba=".95 .3 .3 1">
        <site site="scapula_shoulder_L_flx_site"/>
        <site site="scapula_shoulder_L_flx_site_pass"/>
        <site site="humerus_shoulder_L_flx_site"/>
    </spatial>

    <spatial name="shoulder_R_ext_tendon" rgba=".95 .3 .3 1">
        <site site="scapula_shoulder_R_ext_site"/>
        <site site="scapula_shoulder_R_ext_site_pass"/>
        <site site="humerus_shoulder_R_ext_site"/>
    </spatial>
    <spatial name="shoulder_R_flx_tendon" rgba=".95 .3 .3 1">
        <site site="scapula_shoulder_R_flx_site"/>
        <site site="scapula_shoulder_R_flx_site_pass"/>
        <site site="humerus_shoulder_R_flx_site"/>
    </spatial>

    <spatial name="wrist_L_ext_tendon" rgba=".95 .3 .3 1">
        <site site="radius_wrist_L_ext_site"/>
        <site site="hand_wrist_L_ext_site"/>
    </spatial>
    <spatial name="wrist_L_flx_tendon" rgba=".95 .3 .3 1">
        <site site="radius_wrist_L_flx_site"/>
        <site site="hand_wrist_L_flx_site"/>
    </spatial>

    <spatial name="wrist_R_ext_tendon" rgba=".95 .3 .3 1">
        <site site="radius_wrist_R_ext_site"/>
        <site site="hand_wrist_R_ext_site"/>
    </spatial>
    <spatial name="wrist_R_flx_tendon" rgba=".95 .3 .3 1">
        <site site="radius_wrist_R_flx_site"/>
        <site site="hand_wrist_R_flx_site"/>
    </spatial>
  </tendon>

  <actuator>

    <! Note that the ext and flx muscles are switched!!!! This is so that the neural network for the hindlimbs can be applied to the forelimbs >
    <muscle name="R_hip_joint_ext_muscle" tendon="hip_R_ext_tendon" class="muscle"/>
    <muscle name="R_hip_joint_flx_muscle" tendon="hip_R_flx_tendon" class="muscle"/>

    <muscle name="R_knee_joint_ext_muscle" tendon="knee_R_ext_tendon" class="muscle"/>
    <muscle name="R_knee_joint_flx_muscle" tendon="knee_R_flx_tendon" class="muscle"/>

    <muscle name="R_ankle_joint_ext_muscle" tendon="ankle_R_ext_tendon" class="muscle"/>
    <muscle name="R_ankle_joint_flx_muscle" tendon="ankle_R_flx_tendon" class="muscle"/>
    
    <muscle name="L_hip_joint_ext_muscle" tendon="hip_L_ext_tendon" class="muscle"/>
    <muscle name="L_hip_joint_flx_muscle" tendon="hip_L_flx_tendon" class="muscle"/>

    <muscle name="L_knee_joint_ext_muscle" tendon="knee_L_ext_tendon" class="muscle"/>
    <muscle name="L_knee_joint_flx_muscle" tendon="knee_L_flx_tendon" class="muscle"/>

    <muscle name="L_ankle_joint_ext_muscle" tendon="ankle_L_ext_tendon" class="muscle"/>
    <muscle name="L_ankle_joint_flx_muscle" tendon="ankle_L_flx_tendon" class="muscle"/>

    <muscle name="R_scapula_joint_ext_muscle" tendon="scapula_R_flx_tendon" class="muscle"/>
    <muscle name="R_scapula_joint_flx_muscle" tendon="scapula_R_ext_tendon" class="muscle"/>

    <muscle name="R_shoulder_joint_ext_muscle" tendon="shoulder_R_ext_tendon" class="muscle"/>
    <muscle name="R_shoulder_joint_flx_muscle" tendon="shoulder_R_flx_tendon" class="muscle"/>

    <muscle name="R_wrist_joint_ext_muscle" tendon="wrist_R_ext_tendon" class="muscle"/>
    <muscle name="R_wrist_joint_flx_muscle" tendon="wrist_R_flx_tendon" class="muscle"/>

    <muscle name="L_scapula_joint_ext_muscle" tendon="scapula_L_flx_tendon" class="muscle"/>
    <muscle name="L_scapula_joint_flx_muscle" tendon="scapula_L_ext_tendon" class="muscle"/>

    <muscle name="L_shoulder_joint_ext_muscle" tendon="shoulder_L_ext_tendon" class="muscle"/>
    <muscle name="L_shoulder_joint_flx_muscle" tendon="shoulder_L_flx_tendon" class="muscle"/>

    <muscle name="L_wrist_joint_ext_muscle" tendon="wrist_L_ext_tendon" class="muscle"/>
    <muscle name="L_wrist_joint_flx_muscle" tendon="wrist_L_flx_tendon" class="muscle"/>

  </actuator>

  <!-- Close the loop for the extra bone in the humerus -->
  <equality>
      <connect body1="humerus_left_0" body2="radius_left" anchor="0 0 -0.1925"/>
      <connect body1="humerus_right_0" body2="radius_right" anchor="0 0 -0.1925"/>
  </equality>

</mujoco>
